<?xml version="1.0" ?>
<robot name="frobit" xmlns:xacro="http://www.ros.org/wiki/xacro">

  <xacro:include filename="$(find mybot_description)/urdf/mybot.gazebo" />
  <xacro:include filename="$(find mybot_description)/urdf/materials.xacro" />

  
  <gazebo reference="chassis">
    <material>Gazebo/Orange</material>
  </gazebo>
  <gazebo reference="link_left_wheel">
    <material>Gazebo/Blue</material>
  </gazebo>
  <gazebo reference="link_right_wheel">
    <material>Gazebo/Blue</material>
  </gazebo>
  <gazebo reference="cam_link">
    <material>Gazebo/DarkGrey</material>
  </gazebo>
  
  <!-- <gazebo>
    <plugin filename="libgazebo_ros_diff_drive.so" name="differential_drive_controller">
      <legacyMode>false</legacyMode>
      <alwaysOn>true</alwaysOn>
      <updateRate>20</updateRate>
      <leftJoint>right_wheel_hinge</leftJoint>
      <rightJoint>left_wheel_hinge</rightJoint>
      <wheelSeparation>0.2</wheelSeparation>
      <wheelDiameter>0.2</wheelDiameter>
      <torque>0.1</torque>
      <commandTopic>cmd_vel</commandTopic>
      <odometryTopic>odom</odometryTopic>
      <odometryFrame>odom</odometryFrame>
      <robotBaseFrame>chassis</robotBaseFrame>
    </plugin>
  </gazebo> -->

  


  <link name="chassis">
    <!-- pose and inertial -->
    <pose>0 0 0.1 0 0 0</pose>
    <inertial>
      <mass value="5"/>
      <origin rpy="0 0 0" xyz="0 0 0.1"/>
      <inertia ixx="0.0395416666667" ixy="0" ixz="0" iyy="0.106208333333" iyz="0" izz="0.106208333333"/>
    </inertial>
    <!-- body -->
    <collision name="collision_chassis">
      <geometry>
        <box size="0.5 0.3 0.07"/>
      </geometry>
    </collision>
    <visual>
       <origin xyz="0 0 0.06" rpy="0.0 0.0 -1.57" />
       <geometry>
          <mesh filename="package://mybot_description/meshes/frobit_base.stl" />
        </geometry>
    </visual>
    <!-- caster front -->
    <collision name="caster_front_collision">
      <origin rpy=" 0 0 0" xyz="0.35 0 -0.05"/>
      <geometry>
        <sphere radius="0.05"/>
      </geometry>
      <surface>
        <friction>
          <ode>
            <mu>0</mu>
            <mu2>0</mu2>
            <slip1>1.0</slip1>
            <slip2>1.0</slip2>
          </ode>
        </friction>
      </surface>
    </collision>
    <visual name="caster_front_visual">
      <origin xyz="0.15 0 0.06" rpy=" 0 0 -1.57"/>
      <geometry>
        <mesh filename="package://mybot_description/meshes/front_wheel.stl" />
      </geometry>
    </visual>
  </link>
  
  <link name="link_right_wheel">
    <inertial>
      <mass value="0.2"/>
      <origin rpy="0 1.5707 1.5707" xyz="0 0 0"/>
      <inertia ixx="0.000526666666667" ixy="0" ixz="0" iyy="0.000526666666667" iyz="0" izz="0.001"/>
    </inertial>
    <collision name="link_right_wheel_collision">
      <origin rpy="0 1.5707 1.5707" xyz="0 0 0"/>
      <geometry>
        <cylinder length="0.04" radius="0.1"/>
      </geometry>
    </collision>
    <visual name="link_right_wheel_visual">
      <origin xyz="0 0 0.0" rpy="1.57 0 -1.57"/>
      <geometry>
        <mesh filename="package://mybot_description/meshes/frobit_wheel.stl" />
      </geometry>
    </visual>
  </link>
  
  <joint name="right_wheel_hinge" type="continuous">
    <origin rpy="0 0 0" xyz="-0.05 0.15 0"/>
    <child link="link_right_wheel"/>
    <parent link="chassis"/>
    <axis rpy="0 0 0" xyz="0 1 0"/>
    <limit effort="10000" velocity="1000"/>
    <joint_properties damping="1.0" friction="1.0"/>
  </joint>
  
  <link name="link_left_wheel">
    <inertial>
      <mass value="0.2"/>
      <origin rpy="0 1.5707 1.5707" xyz="0 0 0"/>
      <inertia ixx="0.000526666666667" ixy="0" ixz="0" iyy="0.000526666666667" iyz="0" izz="0.001"/>
    </inertial>
    <collision name="link_left_wheel_collision">
      <origin rpy="0 1.5707 1.5707" xyz="0 0 0"/>
      <geometry>
        <cylinder length="0.04" radius="0.1"/>
      </geometry>
    </collision>
    <visual name="link_left_wheel_visual">
      <origin xyz="0 0 0.0" rpy="1.57 0 1.57"/>
      <geometry>
        <mesh filename="package://mybot_description/meshes/frobit_wheel.stl" />
      </geometry>
    </visual>
  </link>
  
  <joint name="left_wheel_hinge" type="continuous">
    <origin rpy="0 0 0" xyz="-0.05 -0.15 0"/>
    <child link="link_left_wheel"/>
    <parent link="chassis"/>
    <axis rpy="0 0 0" xyz="0 1 0"/>
    <limit effort="10000" velocity="1000"/>
    <joint_properties damping="1.0" friction="1.0"/>
  </joint>

   <!-- Sensors -->
  <link name="cam_link">
    <collision name="cam_collision">
      <origin xyz="0 0 0" rpy="0 0 0"/>
      <geometry>
        <box size="0.05 0.05 0.05"/>
      </geometry>
    </collision>
    <visual name="cam_vis">
      <origin xyz="0 0 0" rpy="0 0 -1.5707"/>
      <geometry>
        <box size="0.05 0.05 0.05"/>
      </geometry>
    </visual>
  </link>

  <joint type="fixed" name="cam_joint">
    <origin xyz="0 -0.10 0.1" rpy="0 0 -1.5707"/>
    <child link="cam_link"/>
    <parent link="chassis"/>
    <axis xyz="0 0 0" />
  </joint>
  

  <link name="gps_link">
    <visual>
      <origin xyz="0 0 0" rpy="0 0 0" />
      <geometry>
        <box size="0.01 0.01 0.01" />          
      </geometry>
    </visual>
    <collision>
      <origin xyz="0 0 0" rpy="0 0 0" />
      <geometry>
        <box size="0.01 0.01 0.01" />
      </geometry>
    </collision>
  </link>
  <joint name="gps_joint" type="fixed">
    <origin xyz="0 0 0.085"/>
    <parent link="chassis"/>
    <child link="gps_link"/>
  </joint>

  <link name="laser"> 
     <collision name="collision_right_wheel">
      <origin xyz="0 0 -0.04" rpy="0 0 0"/>
      <geometry>
        <mesh filename="package://mybot_description/meshes/hokuyo.dae" />
      </geometry>
    </collision>
	<visual> 
<origin xyz="0 0 -0.04" rpy="0 0 0"/>
	<geometry> 
	<mesh filename="package://mybot_description/meshes/hokuyo.dae" />
 	</geometry> 
	<material name="Green"/> 
	</visual> 
	<inertial>
<origin xyz="0 0 -0.035 " rpy="0 0 0"/>
 	<mass value="0.001"/> 
	<inertia 
	ixx="0.0001" ixy="0.0" ixz="0.0" 
	iyy="0.0001" iyz="0.0"
 	izz="0.0001"/>
 	</inertial>
 </link>
 <joint name="laser_joint" type="fixed">
    <origin xyz="0.17 0 0.15" rpy="0 0 0" />
    <parent link="chassis" />
    <child link="laser" />
  </joint>

</robot>